<?xml version="1.0" encoding="utf-8"?>
<!-- This URDF was automatically created by SolidWorks to URDF Exporter! Originally created by Stephen Brawner (brawner@gmail.com) 
     Commit Version: 1.6.0-1-g15f4949  Build Version: 1.6.7594.29634
     For more information, please see http://wiki.ros.org/sw_urdf_exporter -->
<robot
  name="drok3_description2">
  
  <link
    name="base_link">
    <inertial>
      <origin
        xyz="0.0916307721495936 -0.000335907486689213 0.0569327313017182"
        rpy="0 0 0" />
      <mass
        value="38.3049580066646" />
      <inertia
        ixx="0.189675133128325"
        ixy="-6.87158011192175E-05"
        ixz="-0.111395385918992"
        iyy="0.808757796453613"
        iyz="-7.34722853353462E-05"
        izz="0.813726568476578" />
    </inertial>
    <visual>
      <origin
        xyz="0 0 0"
        rpy="0 0 0" />
      <geometry>
        <mesh
          filename="package://drok3_description2/meshes/base_link.STL" />
      </geometry>
      <material
        name="">
        <color
          rgba="0.298039215686275 0.298039215686275 0.298039215686275 1" />
      </material>
    </visual>
    <!--<collision>
      <origin
        xyz="0 0 0"
        rpy="0 0 0" />
      <geometry>
        <mesh
          filename="package://drok3_description2/meshes/base_link.STL" />
      </geometry>
    </collision>-->
  </link>

  <link
    name="R1_link">
    <inertial>
      <origin
        xyz="-2.97278207574136E-06 0 -2.08206009358336E-06"
        rpy="0 0 0" />
      <mass
        value="0.697502716828587" />
      <inertia
        ixx="0.00107179989446096"
        ixy="-3.17556586931068E-18"
        ixz="-1.07013112858152E-08"
        iyy="0.00188983973588254"
        iyz="9.0339996868056E-19"
        izz="0.00107180767895577" />
    </inertial>
    <visual>
      <origin
        xyz="0 0 0"
        rpy="0 0 0" />
      <geometry>
        <mesh
          filename="package://drok3_description2/meshes/R1_link.STL" />
      </geometry>
      <material
        name="">
        <color
          rgba="1.0 0.4 0.0308039215686275 0" />
      </material>
    </visual>
    <collision>
      <origin
        xyz="0 0 0"
        rpy="0 0 0" />
      <geometry>
        <mesh
          filename="package://drok3_description2/meshes/R1_link.STL" />
      </geometry>
    </collision>
  </link>
  <joint
    name="R1_link_joint"
    type="continuous">
    <origin
      xyz="-0.27424 -0.25972 -0.028"
      rpy="0 0 0" />
    <parent
      link="base_link" />
    <child
      link="R1_link" />
    <axis
      xyz="0 1 0" />
  </joint>
  <link
    name="R2_link">
    <inertial>
      <origin
        xyz="-3.60518028585943E-06 0 -2.08206009358336E-06"
        rpy="0 0 0" />
      <mass
        value="0.697502716828588" />
      <inertia
        ixx="0.00107179270224566"
        ixy="-3.20129434385429E-18"
        ixz="-2.60812953021254E-09"
        iyy="0.00188983973588254"
        iyz="9.59223116284526E-19"
        izz="0.00107181487117107" />
    </inertial>
    <visual>
      <origin
        xyz="0 0 0"
        rpy="0 0 0" />
      <geometry>
        <mesh
          filename="package://drok3_description2/meshes/R2_link.STL" />
      </geometry>
      <material
        name="">
        <color
          rgba="1.0 0.4 0.0380039215686275 1" />
      </material>
    </visual>
    <collision>
      <origin
        xyz="0 0 0"
        rpy="0 0 0" />
      <geometry>
        <mesh
          filename="package://drok3_description2/meshes/R2_link.STL" />
      </geometry>
    </collision>
  </link>
  <joint
    name="R2_link_joint"
    type="continuous">
    <origin
      xyz="0.27576 -0.25972 -0.028"
      rpy="0 0 0" />
    <parent
      link="base_link" />
    <child
      link="R2_link" />
    <axis
      xyz="0 1 0" />
  </joint>
  <link
    name="R3_link">
    <inertial>
      <origin
        xyz="3.24700269704881E-06 -5.55111512312578E-17 1.62153661337205E-06"
        rpy="0 0 0" />
      <mass
        value="0.697502716828588" />
      <inertia
        ixx="0.00107179694558754"
        ixy="-3.07511556235849E-18"
        ixz="-9.10311589437715E-09"
        iyy="0.00188983973588254"
        iyz="7.7907126344076E-19"
        izz="0.00107181062782919" />
    </inertial>
    <visual>
      <origin
        xyz="0 0 0"
        rpy="0 0 0" />
      <geometry>
        <mesh
          filename="package://drok3_description2/meshes/R3_link.STL" />
      </geometry>
      <material
        name="">
        <color
          rgba="102 51 0.498039215686275 1" />
      </material>
    </visual>
    <collision>
      <origin
        xyz="0 0 0"
        rpy="0 0 0" />
      <geometry>
        <mesh
          filename="package://drok3_description2/meshes/R3_link.STL" />
      </geometry>
    </collision>
  </link>
  <joint
    name="R3_link_joint"
    type="continuous">
    <origin
      xyz="0.48054 -0.25972 0.16296"
      rpy="0 0 0" />
    <parent
      link="base_link" />
    <child
      link="R3_link" />
    <axis
      xyz="0 1 0" />
  </joint>
  <link
    name="L1_link">
    <inertial>
      <origin
        xyz="-3.60518028584556E-06 -1.11022302462516E-16 -2.08206009358336E-06"
        rpy="0 0 0" />
      <mass
        value="0.697502716828587" />
      <inertia
        ixx="0.00107179270224566"
        ixy="-3.16860373019229E-18"
        ixz="-2.6081295301747E-09"
        iyy="0.00188983973588254"
        iyz="7.92650267045416E-19"
        izz="0.00107181487117107" />
    </inertial>
    <visual>
      <origin
        xyz="0 0 0"
        rpy="0 0 0" />
      <geometry>
        <mesh
          filename="package://drok3_description2/meshes/L1_link.STL" />
      </geometry>
      <material
        name="">
        <color
          rgba="1.0 0.4 0.0308039215686275 1" />
      </material>
    </visual>
    <collision>
      <origin
        xyz="0 0 0"
        rpy="0 0 0" />
      <geometry>
        <mesh
          filename="package://drok3_description2/meshes/L1_link.STL" />
      </geometry>
    </collision>
  </link>
  <joint
    name="L1_link_joint"
    type="continuous">
    <origin
      xyz="-0.27424 0.25972 -0.028"
      rpy="0 0 0" />
    <parent
      link="base_link" />
    <child
      link="L1_link" />
    <axis
      xyz="0 1 0" />
  </joint>
  <link
    name="L2_link">
    <inertial>
      <origin
        xyz="-3.60518028585943E-06 -1.11022302462516E-16 -2.08206009358336E-06"
        rpy="0 0 0" />
      <mass
        value="0.697502716828589" />
      <inertia
        ixx="0.00107179270224566"
        ixy="-3.18775432759348E-18"
        ixz="-2.6081295302701E-09"
        iyy="0.00188983973588254"
        iyz="8.03792722455923E-19"
        izz="0.00107181487117107" />
    </inertial>
    <visual>
      <origin
        xyz="0 0 0"
        rpy="0 0 0" />
      <geometry>
        <mesh
          filename="package://drok3_description2/meshes/L2_link.STL" />
      </geometry>
      <material
        name="">
        <color
          rgba="1.0 0.4 0.0308039215686275 1" />
      </material>
    </visual>
    <collision>
      <origin
        xyz="0 0 0"
        rpy="0 0 0" />
      <geometry>
        <mesh
          filename="package://drok3_description2/meshes/L2_link.STL" />
      </geometry>
    </collision>
  </link>
  <joint
    name="L2_link_joint"
    type="continuous">
    <origin
      xyz="0.27576 0.25972 -0.028"
      rpy="0 0 0" />
    <parent
      link="base_link" />
    <child
      link="L2_link" />
    <axis
      xyz="0 1 0" />
  </joint>
  <link
    name="L3_link">
    <inertial>
      <origin
        xyz="-3.50122690040422E-06 -2.22044604925031E-16 9.55938123270439E-07"
        rpy="0 0 0" />
      <mass
        value="0.697502716828588" />
      <inertia
        ixx="0.00107179397947648"
        ixy="-3.27890477552922E-18"
        ixz="5.78669645348872E-09"
        iyy="0.00188983973588254"
        iyz="7.58660421249286E-19"
        izz="0.00107181359394025" />
    </inertial>
    <visual>
      <origin
        xyz="0 0 0"
        rpy="0 0 0" />
      <geometry>
        <mesh
          filename="package://drok3_description2/meshes/L3_link.STL" />
      </geometry>
      <material
        name="">
        <color
          rgba="1.0 0.4 0.0308039215686275 1" />
      </material>
    </visual>
    <collision>
      <origin
        xyz="0 0 0"
        rpy="0 0 0" />
      <geometry>
        <mesh
          filename="package://drok3_description2/meshes/L3_link.STL" />
      </geometry>
    </collision>
  </link>
  <joint
    name="L3_link_joint"
    type="continuous">
    <origin
      xyz="0.46841 0.25972 0.16296"
      rpy="0 0 0" />
    <parent
      link="base_link" />
    <child
      link="L3_link" />
    <axis
      xyz="0 1 0" />
  </joint>

<gazebo>
  <plugin name="skid_steer_drive_controller" filename="libgazebo_ros_skid_steer_drive.so">
    <updateRate>100.0</updateRate>
    <robotNamespace>/</robotNamespace>
    <leftFrontJoint>L2_link_joint</leftFrontJoint>
    <rightFrontJoint>R2_link_joint</rightFrontJoint>
    <leftRearJoint>L1_link_joint</leftRearJoint>
    <rightRearJoint>R1_link_joint</rightRearJoint>
    <wheelSeparation>0.55</wheelSeparation>
    <wheelDiameter>0.170</wheelDiameter>
    <robotBaseFrame>base_link</robotBaseFrame>
    <torque>10</torque>
    <topicName>cmd_vel</topicName>
    <broadcastTF>true</broadcastTF>
  </plugin>
</gazebo>

<gazebo>
  <plugin name="skid_steer_drive_controller" filename="libgazebo_ros_skid_steer_drive.so">
    <updateRate>100.0</updateRate>
    <robotNamespace>/</robotNamespace>
    <leftFrontJoint>l2_link_joint</leftFrontJoint>
    <rightFrontJoint>r2_link_joint</rightFrontJoint>
    <leftRearJoint>l1_link_joint</leftRearJoint>
    <rightRearJoint>r1_link_joint</rightRearJoint>
    <wheelSeparation>0.55</wheelSeparation>
    <wheelDiameter>0.170</wheelDiameter>
    <robotBaseFrame>base_link</robotBaseFrame>
    <torque>10</torque>
    <topicName>cmd_vel</topicName>
    <broadcastTF>false</broadcastTF>
  </plugin>
</gazebo>

<gazebo>
  <plugin name="skid_steer_drive_controller" filename="libgazebo_ros_skid_steer_drive.so">
    <updateRate>100.0</updateRate>
    <robotNamespace>/</robotNamespace>
    <leftFrontJoint>L3_link_joint</leftFrontJoint>
    <rightFrontJoint>R3_link_joint</rightFrontJoint>
    <leftRearJoint>l4_link_joint</leftRearJoint>
    <rightRearJoint>r4_link_joint</rightRearJoint>
    <wheelSeparation>0.55</wheelSeparation>
    <wheelDiameter>0.170</wheelDiameter>
    <robotBaseFrame>base_link</robotBaseFrame>
    <torque>10</torque>
    <topicName>cmd_vel</topicName>
    <broadcastTF>false</broadcastTF>
  </plugin>
</gazebo>
<gazebo>
  <plugin name="skid_steer_drive_controller" filename="libgazebo_ros_skid_steer_drive.so">
    <updateRate>100.0</updateRate>
    <robotNamespace>/</robotNamespace>
    <leftFrontJoint>l6_link_joint</leftFrontJoint>
    <rightFrontJoint>r6_link_joint</rightFrontJoint>
    <leftRearJoint>l5_link_joint</leftRearJoint>
    <rightRearJoint>r5_link_joint</rightRearJoint>
    <wheelSeparation>0.55</wheelSeparation>
    <wheelDiameter>0.170</wheelDiameter>
    <robotBaseFrame>base_link</robotBaseFrame>
    <torque>10</torque>
    <topicName>cmd_vel</topicName>
    <broadcastTF>false</broadcastTF>
  </plugin>
</gazebo>
<gazebo>
  <plugin name="skid_steer_drive_controller" filename="libgazebo_ros_skid_steer_drive.so">
    <updateRate>100.0</updateRate>
    <robotNamespace>/</robotNamespace>
    <leftFrontJoint>l7_link_joint</leftFrontJoint>
    <rightFrontJoint>r7_link_joint</rightFrontJoint>
    <leftRearJoint>l8_link_joint</leftRearJoint>
    <rightRearJoint>r8_link_joint</rightRearJoint>
    <wheelSeparation>0.55</wheelSeparation>
    <wheelDiameter>0.170</wheelDiameter>
    <robotBaseFrame>base_link</robotBaseFrame>
    <torque>10</torque>
    <topicName>cmd_vel</topicName>
    <broadcastTF>false</broadcastTF>
  </plugin>
</gazebo>

<gazebo>
  <plugin name="skid_steer_drive_controller" filename="libgazebo_ros_skid_steer_drive.so">
    <updateRate>100.0</updateRate>
    <robotNamespace>/</robotNamespace>
    <leftFrontJoint>l9_link_joint</leftFrontJoint>
    <rightFrontJoint>r9_link_joint</rightFrontJoint>
    <leftRearJoint>l10_link_joint</leftRearJoint>
    <rightRearJoint>r10_link_joint</rightRearJoint>
    <wheelSeparation>0.55</wheelSeparation>
    <wheelDiameter>0.170</wheelDiameter>
    <robotBaseFrame>base_link</robotBaseFrame>
    <torque>10</torque>
    <topicName>cmd_vel</topicName>
    <broadcastTF>false</broadcastTF>
  </plugin>
</gazebo>


<gazebo>
  <plugin name="skid_steer_drive_controller" filename="libgazebo_ros_skid_steer_drive.so">
    <updateRate>100.0</updateRate>
    <robotNamespace>/</robotNamespace>
    <leftFrontJoint>l12_link_joint</leftFrontJoint>
    <rightFrontJoint>r12_link_joint</rightFrontJoint>
    <leftRearJoint>l11_link_joint</leftRearJoint>
    <rightRearJoint>r11_link_joint</rightRearJoint>
    <wheelSeparation>0.55</wheelSeparation>
    <wheelDiameter>0.170</wheelDiameter>
    <robotBaseFrame>base_link</robotBaseFrame>
    <torque>10</torque>
    <topicName>cmd_vel</topicName>
    <broadcastTF>false</broadcastTF>
  </plugin>
</gazebo>












 <link
    name="r1_link">
    <inertial>
      <origin
        xyz="-2.77278207574136E-06 0 -2.08206009358336E-06"
        rpy="0 0 0" />
      <mass
        value="0.697502716828587" />
      <inertia
        ixx="0.00107179989446096"
        ixy="-3.17556586931068E-18"
        ixz="-1.07013112858152E-08"
        iyy="0.00188983973588254"
        iyz="9.0339996868056E-19"
        izz="0.00107180767895577" />
    </inertial>
    <!--<visual>
      <origin
        xyz="0 0 0"
        rpy="0 0 0" />
      <geometry>
        <mesh
          filename="package://drok3_description2/meshes/R1_link.STL" />
      </geometry>
      <material
        name="red">
        <color
          rgba="1.0 1.0 0.0308039215686275 0" />
      </material>
    </visual>-->
    <collision>
      <origin
        xyz="0 0 0"
        rpy="0 0 0" />
      <geometry>
        <mesh
          filename="package://drok3_description2/meshes/R1_link.STL" />
      </geometry>
    </collision>
  </link>
  <joint
    name="r1_link_joint"
    type="continuous">
    <origin
      xyz="-0.07424 -0.25972 -0.028"
      rpy="0 0 0" />
    <parent
      link="base_link" />
    <child
      link="r1_link" />
    <axis
      xyz="0 1 0" />
  </joint>

<link
    name="r2_link">
    <inertial>
      <origin
        xyz="-2.57278207574136E-06 0 -2.08206009358336E-06"
        rpy="0 0 0" />
      <mass
        value="0.697502716828587" />
      <inertia
        ixx="0.00107179989446096"
        ixy="-3.17556586931068E-18"
        ixz="-1.07013112858152E-08"
        iyy="0.00188983973588254"
        iyz="9.0339996868056E-19"
        izz="0.00107180767895577" />
    </inertial>
    <!--<visual>
      <origin
        xyz="0 0 0"
        rpy="0 0 0" />
      <geometry>
        <mesh
          filename="package://drok3_description2/meshes/R1_link.STL" />
      </geometry>
      <material
        name="">
        <color
          rgba="1.0 0.4 0.0308039215686275 1" />
      </material>
    </visual>-->
    <collision>
      <origin
        xyz="0 0 0"
        rpy="0 0 0" />
      <geometry>
        <mesh
          filename="package://drok3_description2/meshes/R1_link.STL" />
      </geometry>
    </collision>
  </link>
  <joint
    name="r2_link_joint"
    type="continuous">
    <origin
      xyz="0.12576 -0.25972 -0.028"
      rpy="0 0 0" />
    <parent
      link="base_link" />
    <child
      link="r2_link" />
    <axis
      xyz="0 1 0" />
  </joint>








<link
    name="l1_link">
    <inertial>
      <origin
        xyz="-3.40518028584556E-06 -1.11022302462516E-16 -2.08206009358336E-06"
        rpy="0 0 0" />
      <mass
        value="0.697502716828587" />
      <inertia
        ixx="0.00107179270224566"
        ixy="-3.16860373019229E-18"
        ixz="-2.6081295301747E-09"
        iyy="0.00188983973588254"
        iyz="7.92650267045416E-19"
        izz="0.00107181487117107" />
    </inertial>
    <!--<visual>
      <origin
        xyz="0 0 0"
        rpy="0 0 0" />
      <geometry>
        <mesh
          filename="package://drok3_description2/meshes/L1_link.STL" />
      </geometry>
      <material
        name="">
        <color
          rgba="1.0 0.4 0.0308039215686275 0" />
      </material>
    </visual>-->
    <collision>
      <origin
        xyz="0 0 0"
        rpy="0 0 0" />
      <geometry>
        <mesh
          filename="package://drok3_description2/meshes/L1_link.STL" />
      </geometry>
    </collision>
  </link>
  <joint
    name="l1_link_joint"
    type="continuous">
    <origin
      xyz="-0.07424 0.25972 -0.028"
      rpy="0 0 0" />
    <parent
      link="base_link" />
    <child
      link="l1_link" />
    <axis
      xyz="0 1 0" />
  </joint>

<link
    name="l2_link">
    <inertial>
      <origin
        xyz="-3.20518028584556E-06 -1.11022302462516E-16 -2.08206009358336E-06"
        rpy="0 0 0" />
      <mass
        value="0.697502716828587" />
      <inertia
        ixx="0.00107179270224566"
        ixy="-3.16860373019229E-18"
        ixz="-2.6081295301747E-09"
        iyy="0.00188983973588254"
        iyz="7.92650267045416E-19"
        izz="0.00107181487117107" />
    </inertial>
    <!--<visual>
      <origin
        xyz="0 0 0"
        rpy="0 0 0" />
      <geometry>
        <mesh
          filename="package://drok3_description2/meshes/L1_link.STL" />
      </geometry>
      <material
        name="">
        <color
          rgba="1.0 0.4 0.0308039215686275 0" />
      </material>
    </visual>-->
    <collision>
      <origin
        xyz="0 0 0"
        rpy="0 0 0" />
      <geometry>
        <mesh
          filename="package://drok3_description2/meshes/L1_link.STL" />
      </geometry>
    </collision>
  </link>
  <joint
    name="l2_link_joint"
    type="continuous">
    <origin
      xyz="0.12576 0.25972 -0.028"
      rpy="0 0 0" />
    <parent
      link="base_link" />
    <child
      link="l2_link" />
    <axis
      xyz="0 1 0" />
  </joint>








<link
    name="r4_link">
    <inertial>
      <origin
        xyz="-3.49518028585943E-06 0 -4.08428738963028E-07"
        rpy="0 0 0" />
      <mass
        value="0.697502716828588" />
      <inertia
        ixx="0.00107179270224566"
        ixy="-3.20129434385429E-18"
        ixz="-2.60812953021254E-09"
        iyy="0.00188983973588254"
        iyz="9.59223116284526E-19"
        izz="0.00107181487117107" />
    </inertial>
    <!--<visual>
      <origin
        xyz="0 0 0"
        rpy="0 0 0" />
      <geometry>
        <mesh
          filename="package://drok3_description2/meshes/R2_link.STL" />
      </geometry>
      <material
        name="">
        <color
          rgba="1.0 0.4 0.0380039215686275 0" />
      </material>
    </visual>-->
    <collision>
      <origin
        xyz="0 0 0"
        rpy="0 0 0" />
      <geometry>
        <mesh
          filename="package://drok3_description2/meshes/R2_link.STL" />
      </geometry>
    </collision>
  </link>
  <joint
    name="r4_link_joint"
    type="continuous">
    <origin
      xyz="0.38576 -0.25972 0.072"
      rpy="0 0 0" />
    <parent
      link="base_link" />
    <child
      link="r4_link" />
    <axis
      xyz="0 1 0" />
  </joint>




<link
    name="l4_link">
    <inertial>
      <origin
        xyz="-3.49518028585943E-06 -1.11022302462516E-16 -4.0842873894915E-07"
        rpy="0 0 0" />
      <mass
        value="0.697502716828589" />
      <inertia
        ixx="0.00107179270224566"
        ixy="-3.18775432759348E-18"
        ixz="-2.6081295302701E-09"
        iyy="0.00188983973588254"
        iyz="8.03792722455923E-19"
        izz="0.00107181487117107" />
    </inertial>
    <!--<visual>
      <origin
        xyz="0 0 0"
        rpy="0 0 0" />
      <geometry>
        <mesh
          filename="package://drok3_description2/meshes/L2_link.STL" />
      </geometry>
      <material
        name="">
        <color
          rgba="1.0 0.4 0.0308039215686275 1" />
      </material>
    </visual>-->
    <collision>
      <origin
        xyz="0 0 0"
        rpy="0 0 0" />
      <geometry>
        <mesh
          filename="package://drok3_description2/meshes/L2_link.STL" />
      </geometry>
    </collision>
  </link>
  <joint
    name="l4_link_joint"
    type="continuous">
    <origin
      xyz="0.38576 0.25972 0.072"
      rpy="0 0 0" />
    <parent
      link="base_link" />
    <child
      link="l4_link" />
    <axis
      xyz="0 1 0" />
  </joint>






<link
    name="r5_link">
    <inertial>
      <origin
        xyz="-3.54518028585943E-06 0 -4.13428738963028E-07"
        rpy="0 0 0" />
      <mass
        value="0.697502716828588" />
      <inertia
        ixx="0.00107179270224566"
        ixy="-3.20129434385429E-18"
        ixz="-2.60812953021254E-09"
        iyy="0.00188983973588254"
        iyz="9.59223116284526E-19"
        izz="0.00107181487117107" />
    </inertial>
    <!--<visual>
      <origin
        xyz="0 0 0"
        rpy="0 0 0" />
      <geometry>
        <mesh
          filename="package://drok3_description2/meshes/R2_link.STL" />
      </geometry>
      <material
        name="">
        <color
          rgba="1.0 0.4 0.0380039215686275 1" />
      </material>
    </visual>-->
    <collision>
      <origin
        xyz="0 0 0"
        rpy="0 0 0" />
      <geometry>
        <mesh
          filename="package://drok3_description2/meshes/R2_link.STL" />
      </geometry>
    </collision>
  </link>
  <joint
    name="r5_link_joint"
    type="continuous">
    <origin
      xyz="0.33576 -0.25972 0.022"
      rpy="0 0 0" />
    <parent
      link="base_link" />
    <child
      link="r5_link" />
    <axis
      xyz="0 1 0" />
  </joint>




<link
    name="l5_link">
    <inertial>
      <origin
        xyz="-3.54518028585943E-06 -1.11022302462516E-16 -4.1342873894915E-07"
        rpy="0 0 0" />
      <mass
        value="0.697502716828589" />
      <inertia
        ixx="0.00107179270224566"
        ixy="-3.18775432759348E-18"
        ixz="-2.6081295302701E-09"
        iyy="0.00188983973588254"
        iyz="8.03792722455923E-19"
        izz="0.00107181487117107" />
    </inertial>
    <!--<visual>
      <origin
        xyz="0 0 0"
        rpy="0 0 0" />
      <geometry>
        <mesh
          filename="package://drok3_description2/meshes/L2_link.STL" />
      </geometry>
      <material
        name="">
        <color
          rgba="1.0 0.4 0.0308039215686275 1" />
      </material>
    </visual>-->
    <collision>
      <origin
        xyz="0 0 0"
        rpy="0 0 0" />
      <geometry>
        <mesh
          filename="package://drok3_description2/meshes/L2_link.STL" />
      </geometry>
    </collision>
  </link>
  <joint
    name="l5_link_joint"
    type="continuous">
    <origin
      xyz="0.33576 0.25972 0.022"
      rpy="0 0 0" />
    <parent
      link="base_link" />
    <child
      link="l5_link" />
    <axis
      xyz="0 1 0" />
  </joint>


<link
    name="r6_link">
    <inertial>
      <origin
        xyz="-3.44518028585943E-06 0 -4.03428738963028E-07"
        rpy="0 0 0" />
      <mass
        value="0.697502716828588" />
      <inertia
        ixx="0.00107179270224566"
        ixy="-3.20129434385429E-18"
        ixz="-2.60812953021254E-09"
        iyy="0.00188983973588254"
        iyz="9.59223116284526E-19"
        izz="0.00107181487117107" />
    </inertial>
    <!--<visual>
      <origin
        xyz="0 0 0"
        rpy="0 0 0" />
      <geometry>
        <mesh
          filename="package://drok3_description2/meshes/R2_link.STL" />
      </geometry>
      <material
        name="">
        <color
          rgba="1.0 0.4 0.0380039215686275 1" />
      </material>
    </visual>-->
    <collision>
      <origin
        xyz="0 0 0"
        rpy="0 0 0" />
      <geometry>
        <mesh
          filename="package://drok3_description2/meshes/R2_link.STL" />
      </geometry>
    </collision>
  </link>
  <joint
    name="r6_link_joint"
    type="continuous">
    <origin
      xyz="0.43576 -0.25972 0.122"
      rpy="0 0 0" />
    <parent
      link="base_link" />
    <child
      link="r6_link" />
    <axis
      xyz="0 1 0" />
  </joint>




<link
    name="l6_link">
    <inertial>
      <origin
        xyz="-3.44518028585943E-06 -1.11022302462516E-16 -4.0342873894915E-07"
        rpy="0 0 0" />
      <mass
        value="0.697502716828589" />
      <inertia
        ixx="0.00107179270224566"
        ixy="-3.18775432759348E-18"
        ixz="-2.6081295302701E-09"
        iyy="0.00188983973588254"
        iyz="8.03792722455923E-19"
        izz="0.00107181487117107" />
    </inertial>
    <!--<visual>
      <origin
        xyz="0 0 0"
        rpy="0 0 0" />
      <geometry>
        <mesh
          filename="package://drok3_description2/meshes/L2_link.STL" />
      </geometry>
      <material
        name="">
        <color
          rgba="1.0 0.4 0.0308039215686275 1" />
      </material>
    </visual>-->
    <collision>
      <origin
        xyz="0 0 0"
        rpy="0 0 0" />
      <geometry>
        <mesh
          filename="package://drok3_description2/meshes/L2_link.STL" />
      </geometry>
    </collision>
  </link>
  <joint
    name="l6_link_joint"
    type="continuous">
    <origin
      xyz="0.43576 0.25972 0.122"
      rpy="0 0 0" />
    <parent
      link="base_link" />
    <child
      link="l6_link" />
    <axis
      xyz="0 1 0" />
  </joint>




<link
    name="r7_link">
    <inertial>
      <origin
        xyz="-2.72278207574136E-06 0 -2.08206009358336E-06"
        rpy="0 0 0" />
      <mass
        value="0.697502716828587" />
      <inertia
        ixx="0.00107179989446096"
        ixy="-3.17556586931068E-18"
        ixz="-1.07013112858152E-08"
        iyy="0.00188983973588254"
        iyz="9.0339996868056E-19"
        izz="0.00107180767895577" />
    </inertial>
    <!--<visual>
      <origin
        xyz="0 0 0"
        rpy="0 0 0" />
      <geometry>
        <mesh
          filename="package://drok3_description2/meshes/R1_link.STL" />
      </geometry>
      <material
        name="red">
        <color
          rgba="1.0 1.0 0.0308039215686275 0" />
      </material>
    </visual>-->
    <collision>
      <origin
        xyz="0 0 0"
        rpy="0 0 0" />
      <geometry>
        <mesh
          filename="package://drok3_description2/meshes/R1_link.STL" />
      </geometry>
    </collision>
  </link>
  <joint
    name="r7_link_joint"
    type="continuous">
    <origin
      xyz="-0.02424 -0.25972 -0.028"
      rpy="0 0 0" />
    <parent
      link="base_link" />
    <child
      link="r7_link" />
    <axis
      xyz="0 1 0" />
  </joint>

<link
    name="r8_link">
    <inertial>
      <origin
        xyz="-2.82278207574136E-06 0 -2.08206009358336E-06"
        rpy="0 0 0" />
      <mass
        value="0.697502716828587" />
      <inertia
        ixx="0.00107179989446096"
        ixy="-3.17556586931068E-18"
        ixz="-1.07013112858152E-08"
        iyy="0.00188983973588254"
        iyz="9.0339996868056E-19"
        izz="0.00107180767895577" />
    </inertial>
    <!--<visual>
      <origin
        xyz="0 0 0"
        rpy="0 0 0" />
      <geometry>
        <mesh
          filename="package://drok3_description2/meshes/R1_link.STL" />
      </geometry>
      <material
        name="red">
        <color
          rgba="1.0 1.0 0.0308039215686275 0" />
      </material>
    </visual>-->
    <collision>
      <origin
        xyz="0 0 0"
        rpy="0 0 0" />
      <geometry>
        <mesh
          filename="package://drok3_description2/meshes/R1_link.STL" />
      </geometry>
    </collision>
  </link>
  <joint
    name="r8_link_joint"
    type="continuous">
    <origin
      xyz="-0.12424 -0.25972 -0.028"
      rpy="0 0 0" />
    <parent
      link="base_link" />
    <child
      link="r8_link" />
    <axis
      xyz="0 1 0" />
  </joint>


<link
    name="l7_link">
    <inertial>
      <origin
        xyz="-3.35518028584556E-06 -1.11022302462516E-16 -2.08206009358336E-06"
        rpy="0 0 0" />
      <mass
        value="0.697502716828587" />
      <inertia
        ixx="0.00107179270224566"
        ixy="-3.16860373019229E-18"
        ixz="-2.6081295301747E-09"
        iyy="0.00188983973588254"
        iyz="7.92650267045416E-19"
        izz="0.00107181487117107" />
    </inertial>
    <!--<visual>
      <origin
        xyz="0 0 0"
        rpy="0 0 0" />
      <geometry>
        <mesh
          filename="package://drok3_description2/meshes/L1_link.STL" />
      </geometry>
      <material
        name="">
        <color
          rgba="1.0 0.4 0.0308039215686275 0" />
      </material>
    </visual>-->
    <collision>
      <origin
        xyz="0 0 0"
        rpy="0 0 0" />
      <geometry>
        <mesh
          filename="package://drok3_description2/meshes/L1_link.STL" />
      </geometry>
    </collision>
  </link>
  <joint
    name="l7_link_joint"
    type="continuous">
    <origin
      xyz="-0.02424 0.25972 -0.028"
      rpy="0 0 0" />
    <parent
      link="base_link" />
    <child
      link="l7_link" />
    <axis
      xyz="0 1 0" />
  </joint>




<link
    name="l8_link">
    <inertial>
      <origin
        xyz="-3.40518028584556E-06 -1.11022302462516E-16 -2.08206009358336E-06"
        rpy="0 0 0" />
      <mass
        value="0.697502716828587" />
      <inertia
        ixx="0.00107179270224566"
        ixy="-3.16860373019229E-18"
        ixz="-2.6081295301747E-09"
        iyy="0.00188983973588254"
        iyz="7.92650267045416E-19"
        izz="0.00107181487117107" />
    </inertial>
    <!--<visual>
      <origin
        xyz="0 0 0"
        rpy="0 0 0" />
      <geometry>
        <mesh
          filename="package://drok3_description2/meshes/L1_link.STL" />
      </geometry>
      <material
        name="">
        <color
          rgba="1.0 0.4 0.0308039215686275 0" />
      </material>
    </visual>-->
    <collision>
      <origin
        xyz="0 0 0"
        rpy="0 0 0" />
      <geometry>
        <mesh
          filename="package://drok3_description2/meshes/L1_link.STL" />
      </geometry>
    </collision>
  </link>
  <joint
    name="l8_link_joint"
    type="continuous">
    <origin
      xyz="-0.12424 0.25972 -0.028"
      rpy="0 0 0" />
    <parent
      link="base_link" />
    <child
      link="l8_link" />
    <axis
      xyz="0 1 0" />
  </joint>




<link
    name="r9_link">
    <inertial>
      <origin
        xyz="-2.52278207574136E-06 0 -2.08206009358336E-06"
        rpy="0 0 0" />
      <mass
        value="0.697502716828587" />
      <inertia
        ixx="0.00107179989446096"
        ixy="-3.17556586931068E-18"
        ixz="-1.07013112858152E-08"
        iyy="0.00188983973588254"
        iyz="9.0339996868056E-19"
        izz="0.00107180767895577" />
    </inertial>
    <!--<visual>
      <origin
        xyz="0 0 0"
        rpy="0 0 0" />
      <geometry>
        <mesh
          filename="package://drok3_description2/meshes/R1_link.STL" />
      </geometry>
      <material
        name="">
        <color
          rgba="1.0 0.4 0.0308039215686275 1" />
      </material>
    </visual>-->
    <collision>
      <origin
        xyz="0 0 0"
        rpy="0 0 0" />
      <geometry>
        <mesh
          filename="package://drok3_description2/meshes/R1_link.STL" />
      </geometry>
    </collision>
  </link>
  <joint
    name="r9_link_joint"
    type="continuous">
    <origin
      xyz="0.17576 -0.25972 -0.028"
      rpy="0 0 0" />
    <parent
      link="base_link" />
    <child
      link="r9_link" />
    <axis
      xyz="0 1 0" />
  </joint>

<link
    name="r10_link">
    <inertial>
      <origin
        xyz="-2.62278207574136E-06 0 -2.08206009358336E-06"
        rpy="0 0 0" />
      <mass
        value="0.697502716828587" />
      <inertia
        ixx="0.00107179989446096"
        ixy="-3.17556586931068E-18"
        ixz="-1.07013112858152E-08"
        iyy="0.00188983973588254"
        iyz="9.0339996868056E-19"
        izz="0.00107180767895577" />
    </inertial>
    <!--<visual>
      <origin
        xyz="0 0 0"
        rpy="0 0 0" />
      <geometry>
        <mesh
          filename="package://drok3_description2/meshes/R1_link.STL" />
      </geometry>
      <material
        name="">
        <color
          rgba="1.0 0.4 0.0308039215686275 1" />
      </material>
    </visual>-->
    <collision>
      <origin
        xyz="0 0 0"
        rpy="0 0 0" />
      <geometry>
        <mesh
          filename="package://drok3_description2/meshes/R1_link.STL" />
      </geometry>
    </collision>
  </link>
  <joint
    name="r10_link_joint"
    type="continuous">
    <origin
      xyz="0.07576 -0.25972 -0.028"
      rpy="0 0 0" />
    <parent
      link="base_link" />
    <child
      link="r10_link" />
    <axis
      xyz="0 1 0" />
  </joint>




<link
    name="l9_link">
    <inertial>
      <origin
        xyz="-3.15518028584556E-06 -1.11022302462516E-16 -2.08206009358336E-06"
        rpy="0 0 0" />
      <mass
        value="0.697502716828587" />
      <inertia
        ixx="0.00107179270224566"
        ixy="-3.16860373019229E-18"
        ixz="-2.6081295301747E-09"
        iyy="0.00188983973588254"
        iyz="7.92650267045416E-19"
        izz="0.00107181487117107" />
    </inertial>
    <!--<visual>
      <origin
        xyz="0 0 0"
        rpy="0 0 0" />
      <geometry>
        <mesh
          filename="package://drok3_description2/meshes/L1_link.STL" />
      </geometry>
      <material
        name="">
        <color
          rgba="1.0 0.4 0.0308039215686275 0" />
      </material>
    </visual>-->
    <collision>
      <origin
        xyz="0 0 0"
        rpy="0 0 0" />
      <geometry>
        <mesh
          filename="package://drok3_description2/meshes/L1_link.STL" />
      </geometry>
    </collision>
  </link>
  <joint
    name="l9_link_joint"
    type="continuous">
    <origin
      xyz="0.17576 0.25972 -0.028"
      rpy="0 0 0" />
    <parent
      link="base_link" />
    <child
      link="l9_link" />
    <axis
      xyz="0 1 0" />
  </joint>



<link
    name="l10_link">
    <inertial>
      <origin
        xyz="-3.25518028584556E-06 -1.11022302462516E-16 -2.08206009358336E-06"
        rpy="0 0 0" />
      <mass
        value="0.697502716828587" />
      <inertia
        ixx="0.00107179270224566"
        ixy="-3.16860373019229E-18"
        ixz="-2.6081295301747E-09"
        iyy="0.00188983973588254"
        iyz="7.92650267045416E-19"
        izz="0.00107181487117107" />
    </inertial>
    <!--<visual>
      <origin
        xyz="0 0 0"
        rpy="0 0 0" />
      <geometry>
        <mesh
          filename="package://drok3_description2/meshes/L1_link.STL" />
      </geometry>
      <material
        name="">
        <color
          rgba="1.0 0.4 0.0308039215686275 0" />
      </material>
    </visual>-->
    <collision>
      <origin
        xyz="0 0 0"
        rpy="0 0 0" />
      <geometry>
        <mesh
          filename="package://drok3_description2/meshes/L1_link.STL" />
      </geometry>
    </collision>
  </link>
  <joint
    name="l10_link_joint"
    type="continuous">
    <origin
      xyz="0.07576 0.25972 -0.028"
      rpy="0 0 0" />
    <parent
      link="base_link" />
    <child
      link="l10_link" />
    <axis
      xyz="0 1 0" />
  </joint>


<link
    name="r11_link">
    <inertial>
      <origin
        xyz="-2.92278207574136E-06 0 -2.08206009358336E-06"
        rpy="0 0 0" />
      <mass
        value="0.697502716828587" />
      <inertia
        ixx="0.00107179989446096"
        ixy="-3.17556586931068E-18"
        ixz="-1.07013112858152E-08"
        iyy="0.00188983973588254"
        iyz="9.0339996868056E-19"
        izz="0.00107180767895577" />
    </inertial>
    <!--<visual>
      <origin
        xyz="0 0 0"
        rpy="0 0 0" />
      <geometry>
        <mesh
          filename="package://drok3_description2/meshes/R1_link.STL" />
      </geometry>
      <material
        name="">
        <color
          rgba="1.0 0.4 0.0308039215686275 0" />
      </material>
    </visual>-->
    <collision>
      <origin
        xyz="0 0 0"
        rpy="0 0 0" />
      <geometry>
        <mesh
          filename="package://drok3_description2/meshes/R1_link.STL" />
      </geometry>
    </collision>
  </link>
  <joint
    name="r11_link_joint"
    type="continuous">
    <origin
      xyz="-0.22424 -0.25972 -0.028"
      rpy="0 0 0" />
    <parent
      link="base_link" />
    <child
      link="r11_link" />
    <axis
      xyz="0 1 0" />
  </joint>


<link
    name="r12_link">
    <inertial>
      <origin
        xyz="-3.65518028585943E-06 0 -4.18428738963028E-07"
        rpy="0 0 0" />
      <mass
        value="0.697502716828588" />
      <inertia
        ixx="0.00107179270224566"
        ixy="-3.20129434385429E-18"
        ixz="-2.60812953021254E-09"
        iyy="0.00188983973588254"
        iyz="9.59223116284526E-19"
        izz="0.00107181487117107" />
    </inertial>
    <!--<visual>
      <origin
        xyz="0 0 0"
        rpy="0 0 0" />
      <geometry>
        <mesh
          filename="package://drok3_description2/meshes/R2_link.STL" />
      </geometry>
      <material
        name="">
        <color
          rgba="1.0 0.4 0.0380039215686275 1" />
      </material>
    </visual>-->
    <collision>
      <origin
        xyz="0 0 0"
        rpy="0 0 0" />
      <geometry>
        <mesh
          filename="package://drok3_description2/meshes/R2_link.STL" />
      </geometry>
    </collision>
  </link>
  <joint
    name="r12_link_joint"
    type="continuous">
    <origin
      xyz="0.22576 -0.25972 -0.028"
      rpy="0 0 0" />
    <parent
      link="base_link" />
    <child
      link="r12_link" />
    <axis
      xyz="0 1 0" />
  </joint>




<link
    name="l11_link">
    <inertial>
      <origin
        xyz="-3.55518028584556E-06 -1.11022302462516E-16 -2.08206009358336E-06"
        rpy="0 0 0" />
      <mass
        value="0.697502716828587" />
      <inertia
        ixx="0.00107179270224566"
        ixy="-3.16860373019229E-18"
        ixz="-2.6081295301747E-09"
        iyy="0.00188983973588254"
        iyz="7.92650267045416E-19"
        izz="0.00107181487117107" />
    </inertial>
    <!--<visual>
      <origin
        xyz="0 0 0"
        rpy="0 0 0" />
      <geometry>
        <mesh
          filename="package://drok3_description2/meshes/L1_link.STL" />
      </geometry>
      <material
        name="">
        <color
          rgba="1.0 0.4 0.0308039215686275 1" />
      </material>
    </visual>-->
    <collision>
      <origin
        xyz="0 0 0"
        rpy="0 0 0" />
      <geometry>
        <mesh
          filename="package://drok3_description2/meshes/L1_link.STL" />
      </geometry>
    </collision>
  </link>
  <joint
    name="l11_link_joint"
    type="continuous">
    <origin
      xyz="-0.22424 0.25972 -0.028"
      rpy="0 0 0" />
    <parent
      link="base_link" />
    <child
      link="l11_link" />
    <axis
      xyz="0 1 0" />
  </joint>


<link
    name="l12_link">
    <inertial>
      <origin
        xyz="-3.65518028585943E-06 -1.11022302462516E-16 -4.1842873894915E-07"
        rpy="0 0 0" />
      <mass
        value="0.697502716828589" />
      <inertia
        ixx="0.00107179270224566"
        ixy="-3.18775432759348E-18"
        ixz="-2.6081295302701E-09"
        iyy="0.00188983973588254"
        iyz="8.03792722455923E-19"
        izz="0.00107181487117107" />
    </inertial>
    <!--<visual>
      <origin
        xyz="0 0 0"
        rpy="0 0 0" />
      <geometry>
        <mesh
          filename="package://drok3_description2/meshes/L2_link.STL" />
      </geometry>
      <material
        name="">
        <color
          rgba="1.0 0.4 0.0308039215686275 1" />
      </material>
    </visual>-->
    <collision>
      <origin
        xyz="0 0 0"
        rpy="0 0 0" />
      <geometry>
        <mesh
          filename="package://drok3_description2/meshes/L2_link.STL" />
      </geometry>
    </collision>
  </link>
  <joint
    name="l12_link_joint"
    type="continuous">
    <origin
      xyz="0.22576 0.25972 -0.028"
      rpy="0 0 0" />
    <parent
      link="base_link" />
    <child
      link="l12_link" />
    <axis
      xyz="0 1 0" />
  </joint>


<gazebo reference="base_link">
    <gravity>true</gravity>
    <sensor name="imu_sensor" type="imu">
      <always_on>true</always_on>
      <update_rate>100</update_rate>
      <visualize>true</visualize>
      <topic>__default_topic__</topic>
      <plugin filename="libgazebo_ros_imu_sensor.so" name="imu_plugin">
        <topicName>imu</topicName>
        <bodyName>base_link</bodyName>
        <updateRateHZ>100.0</updateRateHZ>
        <gaussianNoise>0.0</gaussianNoise>
        <xyzOffset>0 0 0</xyzOffset>
        <rpyOffset>0 0 0</rpyOffset>
        <frameName>base_link</frameName>
        <initialOrientationAsReference>false</initialOrientationAsReference>
      </plugin>
      <pose>0 0 0 0 0 0</pose>
    </sensor>
  </gazebo>





  <joint name="lidar_joint" type="fixed">
    <axis xyz="0 1 0" />
    <origin xyz="0.5 -0.000335907486689213 0.0569327313017182" rpy="0 0 0"/>
    <parent link="base_link"/>
    <child link="lidar_link"/>
  </joint>

<link
    name="lidar_link">
    <inertial>
      <origin
        xyz="0.5 -0.000335907486689213 0.0569327313017182"
        rpy="0 0 0" />
      <mass

        value="0.5" />
      <inertia ixx="1e-6" ixy="0" ixz="0" iyy="1e-6" iyz="0" izz="1e-6" />
    </inertial>
    <!--<visual>
      <origin
        xyz="0 0 0"
        rpy="0 0 0" />
      <geometry>
        <mesh
          filename="package://drok3_description2/meshes/base_link.STL" />
      </geometry>
      <material
        name="">
        <color
          rgba="0.298039215686275 0.298039215686275 0.298039215686275 1" />
      </material>
    </visual>-->
    <!--<collision>
      <origin
        xyz="0 0 0"
        rpy="0 0 0" />

      <geometry>
        <mesh
          filename="package://drok3_description2/meshes/base_link.STL" />
      </geometry>
    </collision>-->
  </link>

   <!-- hokuyo -->
  <gazebo reference="lidar_link">
    <sensor type="ray" name="head_hokuyo_sensor">
      <pose>0 0 0 0 0 0</pose>
      <visualize>true</visualize>
      <update_rate>100</update_rate>
      <ray>
        <scan>
          <horizontal>
            <samples>360</samples>
            <resolution>1</resolution>
            <min_angle>-3.141592</min_angle>
            <max_angle>3.141592</max_angle>
          </horizontal>
        </scan>
        <range>
          <min>0.10</min>
          <max>3.0</max>
          <resolution>0.05</resolution>
        </range>
        <noise>
          <type>gaussian</type>
          <!-- Noise parameters based on published spec for Hokuyo laser
               achieving "+-30mm" accuracy at range < 10m.  A mean of 0.0m and
               stddev of 0.01m will put 99.7% of samples within 0.03m of the true
               reading. -->
          <mean>0.0</mean>
          <stddev>0.01</stddev>
        </noise>
      </ray>
      <plugin name="gazebo_ros_head_hokuyo_controller" filename="libgazebo_ros_laser.so">
        <topicName>/scan</topicName>
        <frameName>lidar_link</frameName>
      </plugin>
    </sensor>
  </gazebo>





 <gazebo reference="L1_link">
    <kp>1000000.0</kp> <!-- kp and kd for rubber -->
    <kd>10.0</kd>
    <mu1>0.4</mu1> <!-- was 10 -->
    <mu2>1.0</mu2>
<fdir1>0 1 0</fdir1>
      <!-- how to get these into <surface><friction><ode>... ?
        slip1 0.5 /slip1 
         slip2 0 /slip2 
      -->
    <!-- fdir1 0 1 0 /fdir1 --> <!-- see http://github.com/MobileRobots/amr-ros-config/issues/6 -->
    <maxVel>1.0</maxVel>
    <minDepth>0.00</minDepth>
    <material value="Gazebo/Black" />
  </gazebo>


 <gazebo reference="R1_link">
    <kp>1000000.0</kp> <!-- kp and kd for rubber -->
    <kd>10.0</kd>
    <mu1>0.4</mu1> <!-- was 10 -->
    <mu2>1.0</mu2>
<fdir1>0 1 0</fdir1>
      <!-- how to get these into <surface><friction><ode>... ?
        slip1 0.5 /slip1 
         slip2 0 /slip2 
      -->
    <!-- fdir1 0 1 0 /fdir1 --> <!-- see http://github.com/MobileRobots/amr-ros-config/issues/6 -->
    <maxVel>1.0</maxVel>
    <minDepth>0.00</minDepth>
    <material value="Gazebo/Black" />
  </gazebo>


<gazebo reference="L2_link">
    <kp>1000000.0</kp> <!-- kp and kd for rubber -->
    <kd>10.0</kd>
    <mu1>0.4</mu1> <!-- was 10 -->
    <mu2>1.0</mu2>
    <fdir1>0 1 0</fdir1>
      <!-- how to get these into <surface><friction><ode>... ?
        slip1 0.5 /slip1 
         slip2 0 /slip2 
      -->
    <!-- fdir1 0 1 0 /fdir1 --> <!-- see http://github.com/MobileRobots/amr-ros-config/issues/6 -->
    <maxVel>1.0</maxVel>
    <minDepth>0.00</minDepth>
    <material value="Gazebo/Black" />
  </gazebo>

<gazebo reference="R2_link">
    <kp>1000000.0</kp> <!-- kp and kd for rubber -->
    <kd>10.0</kd>
    <mu1>0.4</mu1> <!-- was 10 -->
    <mu2>1.0</mu2>
<fdir1>0 1 0</fdir1>
      <!-- how to get these into <surface><friction><ode>... ?
        slip1 0.5 /slip1 
         slip2 0 /slip2 
      -->
    <!-- fdir1 0 1 0 /fdir1 --> <!-- see http://github.com/MobileRobots/amr-ros-config/issues/6 -->
    <maxVel>1.0</maxVel>
    <minDepth>0.00</minDepth>
    <material value="Gazebo/Black" />
  </gazebo>


 <gazebo reference="l1_link">
    <kp>1000000.0</kp> <!-- kp and kd for rubber -->
    <kd>100.0</kd>
    <mu1>0.4</mu1> <!-- was 10 -->
    <mu2>1.0</mu2>
<fdir1>0 1 0</fdir1>
      <!-- how to get these into <surface><friction><ode>... ?
        slip1 0.5 /slip1 
         slip2 0 /slip2 
      -->
    <!-- fdir1 0 1 0 /fdir1 --> <!-- see http://github.com/MobileRobots/amr-ros-config/issues/6 -->
    <maxVel>1.0</maxVel>
    <minDepth>0.00</minDepth>
    <!--<material value="Gazebo/Black" />-->
  </gazebo>

<gazebo reference="l2_link">
    <kp>1000000.0</kp> <!-- kp and kd for rubber -->
    <kd>100.0</kd>
    <mu1>0.4</mu1> <!-- was 10 -->
    <mu2>1.0</mu2>
<fdir1>0 1 0</fdir1>
      <!-- how to get these into <surface><friction><ode>... ?
        slip1 0.5 /slip1 
         slip2 0 /slip2 
      -->
    <!-- fdir1 0 1 0 /fdir1 --> <!-- see http://github.com/MobileRobots/amr-ros-config/issues/6 -->
    <maxVel>1.0</maxVel>
    <minDepth>0.00</minDepth>
    <!--<material value="Gazebo/Black" />-->
  </gazebo>

<gazebo reference="l3_link">
    <kp>1000000.0</kp> <!-- kp and kd for rubber -->
    <kd>100.0</kd>
    <mu1>0.4</mu1> <!-- was 10 -->
    <mu2>1.0</mu2>
<fdir1>0 1 0</fdir1>
      <!-- how to get these into <surface><friction><ode>... ?
        slip1 0.5 /slip1 
         slip2 0 /slip2 
      -->
    <!-- fdir1 0 1 0 /fdir1 --> <!-- see http://github.com/MobileRobots/amr-ros-config/issues/6 -->
    <maxVel>1.0</maxVel>
    <minDepth>0.00</minDepth>
    <!--<material value="Gazebo/Black" />-->
  </gazebo>
<gazebo reference="l4_link">
    <kp>1000000.0</kp> <!-- kp and kd for rubber -->
    <kd>1.0</kd>
    <mu1>0.4</mu1> <!-- was 10 -->
    <mu2>1.0</mu2>
<fdir1>0 1 0</fdir1>
      <!-- how to get these into <surface><friction><ode>... ?
        slip1 0.5 /slip1 
         slip2 0 /slip2 
      -->
    <!-- fdir1 0 1 0 /fdir1 --> <!-- see http://github.com/MobileRobots/amr-ros-config/issues/6 -->
    <maxVel>1.0</maxVel>
    <minDepth>0.00</minDepth>
    <!--<material value="Gazebo/Black" />-->
  </gazebo>
<gazebo reference="l5_link">
    <kp>1000000.0</kp> <!-- kp and kd for rubber -->
    <kd>100.0</kd>
    <mu1>0.4</mu1> <!-- was 10 -->
    <mu2>1.0</mu2>
<fdir1>0 1 0</fdir1>
      <!-- how to get these into <surface><friction><ode>... ?
        slip1 0.5 /slip1 
         slip2 0 /slip2 
      -->
    <!-- fdir1 0 1 0 /fdir1 --> <!-- see http://github.com/MobileRobots/amr-ros-config/issues/6 -->
    <maxVel>1.0</maxVel>
    <minDepth>0.00</minDepth>
    <!--<material value="Gazebo/Black" />-->
  </gazebo>
<gazebo reference="l6_link">
    <kp>1000000.0</kp> <!-- kp and kd for rubber -->
    <kd>100.0</kd>
    <mu1>0.4</mu1> <!-- was 10 -->
    <mu2>1.0</mu2>
<fdir1>0 1 0</fdir1>
      <!-- how to get these into <surface><friction><ode>... ?
        slip1 0.5 /slip1 
         slip2 0 /slip2 
      -->
    <!-- fdir1 0 1 0 /fdir1 --> <!-- see http://github.com/MobileRobots/amr-ros-config/issues/6 -->
    <maxVel>1.0</maxVel>
    <minDepth>0.00</minDepth>
    <!--<material value="Gazebo/Black" />-->
  </gazebo>
<gazebo reference="l7_link">
    <kp>1000000.0</kp> <!-- kp and kd for rubber -->
    <kd>100.0</kd>
    <mu1>0.4</mu1> <!-- was 10 -->
    <mu2>100.0</mu2>
<fdir1>0 1 0</fdir1>
      <!-- how to get these into <surface><friction><ode>... ?
        slip1 0.5 /slip1 
         slip2 0 /slip2 
      -->
    <!-- fdir1 0 1 0 /fdir1 --> <!-- see http://github.com/MobileRobots/amr-ros-config/issues/6 -->
    <maxVel>1.0</maxVel>
    <minDepth>0.00</minDepth>
    <!--<material value="Gazebo/Black" />-->
  </gazebo>
<gazebo reference="l8_link">
    <kp>1000000.0</kp> <!-- kp and kd for rubber -->
    <kd>100.0</kd>
    <mu1>0.4</mu1> <!-- was 10 -->
    <mu2>100.0</mu2>
<fdir1>0 1 0</fdir1>
      <!-- how to get these into <surface><friction><ode>... ?
        slip1 0.5 /slip1 
         slip2 0 /slip2 
      -->
    <!-- fdir1 0 1 0 /fdir1 --> <!-- see http://github.com/MobileRobots/amr-ros-config/issues/6 -->
    <maxVel>1.0</maxVel>
    <minDepth>0.00</minDepth>
    <!--<material value="Gazebo/Black" />-->
  </gazebo>
<gazebo reference="l9_link">
    <kp>1000000.0</kp> <!-- kp and kd for rubber -->
    <kd>1.0</kd>
    <mu1>0.4</mu1> <!-- was 10 -->
    <mu2>1.0</mu2>
<fdir1>0 1 0</fdir1>
      <!-- how to get these into <surface><friction><ode>... ?
        slip1 0.5 /slip1 
         slip2 0 /slip2 
      -->
    <!-- fdir1 0 1 0 /fdir1 --> <!-- see http://github.com/MobileRobots/amr-ros-config/issues/6 -->
    <maxVel>1.0</maxVel>
    <minDepth>0.00</minDepth>
    <!--<material value="Gazebo/Black" />-->
  </gazebo>
<gazebo reference="l10_link">
    <kp>1000000.0</kp> <!-- kp and kd for rubber -->
    <kd>100.0</kd>
    <mu1>0.4</mu1> <!-- was 10 -->
    <mu2>1.0</mu2>
<fdir1>0 1 0</fdir1>
      <!-- how to get these into <surface><friction><ode>... ?
        slip1 0.5 /slip1 
         slip2 0 /slip2 
      -->
    <!-- fdir1 0 1 0 /fdir1 --> <!-- see http://github.com/MobileRobots/amr-ros-config/issues/6 -->
    <maxVel>1.0</maxVel>
    <minDepth>0.00</minDepth>
    <!--<material value="Gazebo/Black" />-->
  </gazebo>
<gazebo reference="l11_link">
    <kp>1000000.0</kp> <!-- kp and kd for rubber -->
    <kd>100.0</kd>
    <mu1>0.7</mu1> <!-- was 10 -->
    <mu2>1.0</mu2>
<fdir1>0 1 0</fdir1>
      <!-- how to get these into <surface><friction><ode>... ?
        slip1 0.5 /slip1 
         slip2 0 /slip2 
      -->
    <!-- fdir1 0 1 0 /fdir1 --> <!-- see http://github.com/MobileRobots/amr-ros-config/issues/6 -->
    <maxVel>1.0</maxVel>
    <minDepth>0.00</minDepth>
    <!--<material value="Gazebo/Black" />-->
  </gazebo>
<gazebo reference="l12_link">
    <kp>1000000.0</kp> <!-- kp and kd for rubber -->
    <kd>100.0</kd>
    <mu1>0.4</mu1> <!-- was 10 -->
    <mu2>1.0</mu2>
<fdir1>0 1 0</fdir1>
      <!-- how to get these into <surface><friction><ode>... ?
        slip1 0.5 /slip1 
         slip2 0 /slip2 
      -->
    <!-- fdir1 0 1 0 /fdir1 --> <!-- see http://github.com/MobileRobots/amr-ros-config/issues/6 -->
    <maxVel>1.0</maxVel>
    <minDepth>0.00</minDepth>
    <!--<material value="Gazebo/Black" />-->
  </gazebo>



<gazebo reference="r1_link">
    <kp>1000000.0</kp> <!-- kp and kd for rubber -->
    <kd>100.0</kd>
    <mu1>0.4</mu1> <!-- was 10 -->
    <mu2>1.0</mu2>
<fdir1>0 1 0</fdir1>
      <!-- how to get these into <surface><friction><ode>... ?
        slip1 0.5 /slip1 
         slip2 0 /slip2 
      -->
    <!-- fdir1 0 1 0 /fdir1 --> <!-- see http://github.com/MobileRobots/amr-ros-config/issues/6 -->
    <maxVel>1.0</maxVel>
    <minDepth>0.00</minDepth>
    <!--<material value="Gazebo/Black" />-->
  </gazebo>
<gazebo reference="r2_link">
    <kp>1000000.0</kp> <!-- kp and kd for rubber -->
    <kd>100.0</kd>
    <mu1>0.4</mu1> <!-- was 10 -->
    <mu2>1.0</mu2>
<fdir1>0 1 0</fdir1>
      <!-- how to get these into <surface><friction><ode>... ?
        slip1 0.5 /slip1 
         slip2 0 /slip2 
      -->
    <!-- fdir1 0 1 0 /fdir1 --> <!-- see http://github.com/MobileRobots/amr-ros-config/issues/6 -->
    <maxVel>1.0</maxVel>
    <minDepth>0.00</minDepth>
    <!--<material value="Gazebo/Black" />-->
  </gazebo>
<gazebo reference="r3_link">
    <kp>1000000.0</kp> <!-- kp and kd for rubber -->
    <kd>100.0</kd>
    <mu1>0.4</mu1> <!-- was 10 -->
    <mu2>1.0</mu2>
<fdir1>0 1 0</fdir1>
      <!-- how to get these into <surface><friction><ode>... ?
        slip1 0.5 /slip1 
         slip2 0 /slip2 
      -->
    <!-- fdir1 0 1 0 /fdir1 --> <!-- see http://github.com/MobileRobots/amr-ros-config/issues/6 -->
    <maxVel>1.0</maxVel>
    <minDepth>0.00</minDepth>
    <!--<material value="Gazebo/Black" />-->
  </gazebo>
<gazebo reference="r4_link">
    <kp>1000000.0</kp> <!-- kp and kd for rubber -->
    <kd>100.0</kd>
    <mu1>0.4</mu1> <!-- was 10 -->
    <mu2>1.0</mu2>
<fdir1>0 1 0</fdir1>
      <!-- how to get these into <surface><friction><ode>... ?
        slip1 0.5 /slip1 
         slip2 0 /slip2 
      -->
    <!-- fdir1 0 1 0 /fdir1 --> <!-- see http://github.com/MobileRobots/amr-ros-config/issues/6 -->
    <maxVel>1.0</maxVel>
    <minDepth>0.00</minDepth>
    <!--<material value="Gazebo/Black" />-->
  </gazebo>
<gazebo reference="r5_link">
    <kp>1000000.0</kp> <!-- kp and kd for rubber -->
    <kd>100.0</kd>
    <mu1>0.4</mu1> <!-- was 10 -->
    <mu2>1.0</mu2>
<fdir1>0 1 0</fdir1>
      <!-- how to get these into <surface><friction><ode>... ?
        slip1 0.5 /slip1 
         slip2 0 /slip2 
      -->
    <!-- fdir1 0 1 0 /fdir1 --> <!-- see http://github.com/MobileRobots/amr-ros-config/issues/6 -->
    <maxVel>1.0</maxVel>
    <minDepth>0.00</minDepth>
    <!--<material value="Gazebo/Black" />-->
  </gazebo>
<gazebo reference="r6_link">
    <kp>1000000.0</kp> <!-- kp and kd for rubber -->
    <kd>100.0</kd>
    <mu1>0.4</mu1> <!-- was 10 -->
    <mu2>1.0</mu2>
<fdir1>0 1 0</fdir1>
      <!-- how to get these into <surface><friction><ode>... ?
        slip1 0.5 /slip1 
         slip2 0 /slip2 
      -->
    <!-- fdir1 0 1 0 /fdir1 --> <!-- see http://github.com/MobileRobots/amr-ros-config/issues/6 -->
    <maxVel>1.0</maxVel>
    <minDepth>0.00</minDepth>
    <!--<material value="Gazebo/Black" />-->
  </gazebo>
<gazebo reference="r7_link">
    <kp>1000000.0</kp> <!-- kp and kd for rubber -->
    <kd>100.0</kd>
    <mu1>0.4</mu1> <!-- was 10 -->
    <mu2>100.0</mu2>
<fdir1>0 1 0</fdir1>
      <!-- how to get these into <surface><friction><ode>... ?
        slip1 0.5 /slip1 
         slip2 0 /slip2 
      -->
    <!-- fdir1 0 1 0 /fdir1 --> <!-- see http://github.com/MobileRobots/amr-ros-config/issues/6 -->
    <maxVel>1.0</maxVel>
    <minDepth>0.00</minDepth>
    <!--<material value="Gazebo/Black" />-->
  </gazebo>
<gazebo reference="r8_link">
    <kp>1000000.0</kp> <!-- kp and kd for rubber -->
    <kd>100.0</kd>
    <mu1>0.4</mu1> <!-- was 10 -->
    <mu2>100.0</mu2>
<fdir1>0 1 0</fdir1>
      <!-- how to get these into <surface><friction><ode>... ?
        slip1 0.5 /slip1 
         slip2 0 /slip2 
      -->
    <!-- fdir1 0 1 0 /fdir1 --> <!-- see http://github.com/MobileRobots/amr-ros-config/issues/6 -->
    <maxVel>1.0</maxVel>
    <minDepth>0.00</minDepth>
    <!--<material value="Gazebo/Black" />-->
  </gazebo>
<gazebo reference="r9_link">
    <kp>1000000.0</kp> <!-- kp and kd for rubber -->
    <kd>100.0</kd>
    <mu1>0.4</mu1> <!-- was 10 -->
    <mu2>1.0</mu2>
<fdir1>0 1 0</fdir1>
      <!-- how to get these into <surface><friction><ode>... ?
        slip1 0.5 /slip1 
         slip2 0 /slip2 
      -->
    <!-- fdir1 0 1 0 /fdir1 --> <!-- see http://github.com/MobileRobots/amr-ros-config/issues/6 -->
    <maxVel>1.0</maxVel>
    <minDepth>0.00</minDepth>
    <!--<material value="Gazebo/Black" />-->
  </gazebo>
<gazebo reference="r10_link">
    <kp>1000000.0</kp> <!-- kp and kd for rubber -->
    <kd>100.0</kd>
    <mu1>0.4</mu1> <!-- was 10 -->
    <mu2>1.0</mu2>
<fdir1>0 1 0</fdir1>
      <!-- how to get these into <surface><friction><ode>... ?
        slip1 0.5 /slip1 
         slip2 0 /slip2 
      -->
    <!-- fdir1 0 1 0 /fdir1 --> <!-- see http://github.com/MobileRobots/amr-ros-config/issues/6 -->
    <maxVel>1.0</maxVel>
    <minDepth>0.00</minDepth>
    <!--<material value="Gazebo/Black" />-->
  </gazebo>
<gazebo reference="r11_link">
    <kp>1000000.0</kp> <!-- kp and kd for rubber -->
    <kd>100.0</kd>
    <mu1>0.4</mu1> <!-- was 10 -->
    <mu2>1.0</mu2>
<fdir1>0 1 0</fdir1>
      <!-- how to get these into <surface><friction><ode>... ?
        slip1 0.5 /slip1 
         slip2 0 /slip2 
      -->
    <!-- fdir1 0 1 0 /fdir1 --> <!-- see http://github.com/MobileRobots/amr-ros-config/issues/6 -->
    <maxVel>1.0</maxVel>
    <minDepth>0.00</minDepth>
    <!--<material value="Gazebo/Black" />-->
  </gazebo>
<gazebo reference="r12_link">
    <kp>1000000.0</kp> <!-- kp and kd for rubber -->
    <kd>100.0</kd>
    <mu1>0.4</mu1> <!-- was 10 -->
    <mu2>1.0</mu2>
<fdir1>0 1 0</fdir1>
      <!-- how to get these into <surface><friction><ode>... ?
        slip1 0.5 /slip1 
         slip2 0 /slip2 
      -->
    <!-- fdir1 0 1 0 /fdir1 --> <!-- see http://github.com/MobileRobots/amr-ros-config/issues/6 -->
    <maxVel>1.0</maxVel>
    <minDepth>0.00</minDepth>
    <!--<material value="Gazebo/Black" />-->
  </gazebo>






</robot>
